Workbook
Name Corr_flag: Simulation!$H$1
Name Grid_Layer1_Allocation: Layer1_Allocation!$A$1:$M$26
Name Grid_Layer1_Base: Layer1_Base!$A$1:$I$16
Name Grid_Layer1_Correlation: Layer1_Correlation!$A$1:$Z$29
Name Grid_Layer1_Factors: Layer1_Factors!$A$1:$F$26
Name Grid_Mapping: Mapping!$A$1:$F$46
Name Grid_Methodology: Methodology!$A$1:$C$23
Name Grid_RiskRegister: 'Risk Register'!$A$1:$AE$44
Name List_CGCode: OFFSET(Lists!$F$3,0,0,MAX(COUNTA(Lists!$F$3:$F$1000),1),1)
Name List_Distribution: OFFSET(Lists!$A$3,0,0,MAX(COUNTA(Lists!$A$3:$A$1000),1),1)
Name List_Factor: OFFSET(Lists!$J$3,0,0,MAX(COUNTA(Lists!$J$3:$J$1000),1),1)
Name List_MCInclude: OFFSET(Lists!$B$3,0,0,MAX(COUNTA(Lists!$B$3:$B$1000),1),1)
Name List_Mode: OFFSET(Lists!$E$3,0,0,MAX(COUNTA(Lists!$E$3:$E$1000),1),1)
Name List_Package: OFFSET(Lists!$I$3,0,0,MAX(COUNTA(Lists!$I$3:$I$1000),1),1)
Name List_RBS_L1: OFFSET(Lists!$G$3,0,0,MAX(COUNTA(Lists!$G$3:$G$1000),1),1)
Name List_RBS_L2: OFFSET(Lists!$H$3,0,0,MAX(COUNTA(Lists!$H$3:$H$1000),1),1)
Name List_Recurrence: OFFSET(Lists!$D$3,0,0,MAX(COUNTA(Lists!$D$3:$D$1000),1),1)
Name List_TimeImpact: OFFSET(Lists!$C$3,0,0,MAX(COUNTA(Lists!$C$3:$C$1000),1),1)
Name MC_day_rate: MC_Params!$C$11
Name Out_conv_halfwidth: Simulation!$H$3
Name Out_conv_pct: Simulation!$H$4
Name Out_ptable: Simulation!$A$2:$B$20
Name Out_scurve: Simulation!$D$2:$E$102
Name Out_triple: Simulation!$I$2:$L$20
Name Out_validation: Simulation!$N$2:$N$3
Name Set_Client: 'TOC & Instructions'!$B$63
Name Set_ContractVersion: Settings!$B$6
Name Set_IssueDate: 'TOC & Instructions'!$B$66
Name Set_iterations: Settings!$B$1
Name Set_iterations_max: Settings!$B$5
Name Set_Layer1_Enabled: Settings!$B$8
Name Set_PreparedBy: 'TOC & Instructions'!$B$64
Name Set_ProjectName: 'TOC & Instructions'!$B$61
Name Set_ProjectNumber: 'TOC & Instructions'!$B$62
Name Set_Revision: 'TOC & Instructions'!$B$65
Name Set_risk_prefix: Settings!$B$4
Name Set_seed: Settings!$B$2
Name Set_view: Settings!$B$3

Sheet TOC & Instructions
A1: Cost-QRA Register - project input document
A2: Scaffolded once by tools/register_scaffold.py, then this file is yours - fill it in, it is standalone. Re-scaffolding is never run against a live register.
A3: Register contract | B3: =Settings!B6 -> 1.4 | C3: The engine checks this on every run and refuses on any mismatch. Shown here from Settings!B6, never typed twice.
A4: Tabs, in the order you fill them (auto-generated from the sheet inventory)
A5: MC_Params | B5: Engine run parameters: day rate, programme seasons, CP threshold, TIC. Fill the day rate or schedule-dollar figures stay zero. Settings holds iterations/seed/view. | C5: you fill
A6: Lists | B6: Cascade lists - edit here; the dropdowns follow. | C6: you fill
A7: Risk Register | B7: Event risks - cost + schedule three-point inputs, EMV. | C7: you fill
A8: Mapping | B8: P6/CPM binding for schedule (Time=Yes) risks. | C8: you fill
A9: Risk_Activity_Patterns | B9: Schedule risk-to-activity patterns - workshop input, you fill this. | C9: you fill
A10: Risk_Pattern_Assignments | B10: Per-risk pattern assignment - workshop input, you fill this. | C10: you fill
A11: Treatments | B11: Per-risk treatments + effectiveness - workshop input, you fill this. | C11: you fill
A12: Methodology | B12: CG correlation coefficients + Mode multipliers. | C12: you fill
A13: Settings | B13: Run settings (iterations/seed/view/prefix); the LIVE run-config surface. | C13: you fill
A14: Layer1_Base | B14: Layer-1 base estimate matrix. | C14: you fill
A15: Layer1_Factors | B15: Layer-1 risk factors. | C15: you fill
A16: Layer1_Allocation | B16: Layer-1 factor x WBS allocation. | C16: you fill
... A21: Reference (xlwings) | B21: xlwings requirements + @script (paste-once). | C21: reference
A26: Cell-type legend
A27: input | B27: Blue font, unlocked - you fill this in.
A28: calc | B28: Black font, locked - a live Excel formula (do not overwrite).
A29: model | B29: Amber fill - written by the model each run; do not edit.
A30: model-read | B30: Thin blue border - the Python model reads this cell (may also be an input).
A32: Methodology defaults
B33: The Methodology tab ships with CG coefficients defaulted to 0.5 - review / elicit per project. Mode multipliers (Series 1.0 / Hybrid 0.5 / Parallel 0.0) are locked methodology constants.
A35: Layer 1 - deterministic factor model (optional)
B36: The four Layer1_* tabs and the EMV & Mode Analysis tab are STANDARD on every register, but Layer 1 ships OFF: Settings!Set_Layer1_Enabled = FALSE, so the blank grids have NIL impact and the register reads exactly as a cost-only project. The grids ship at their real shape, blank: Layer1_Base is 12 placeholder WBS rows x 8 resource columns, in $M; Layer1_Allocation is 25 factor rows x the same WBS columns; Layer1_Correlation is a 25-factor lower triangle. To use Layer 1: (1) on Layer1_Base rename the WBS rows you need and type each row's $M by column, then the Declared_Total. A row with no numbers is ignored, so type 0 for a genuine zero. (2) On Layer1_Allocation rename the same WBS columns to match Layer1_Base EXACTLY - the model matches the two by name and refuses a mismatch; unused placeholder columns can stay. List your factors on Layer1_Factors (pick names from the dropdown) and tick their WBS cells with x. (3) On Layer1_Correlation type the correlated factor names across row 4 and down column A in the same order, and the coefficients in the blue lower triangle; grey cells are never read, and a blank pair means 0. (4) ONLY THEN set Set_Layer1_Enabled = TRUE. Turning Layer 1 on before the grids are filled is refused with a message naming the tab. The EMV & Mode Analysis tab (totals + charts) populates from the register EMV columns whenever the register is filled or a run happens. Leave the flag FALSE to keep Layer 1 off. A project needing more rows regenerates with build_template(n_layer1_wbs_rows=, n_layer1_factors=).
A38: Sheet protection (REG04)
B39: The machine tabs are protected (no password): input cells are unlocked, the contract cells + formulas are locked, and the workbook structure is locked so tabs cannot be deleted/reordered. This guards against accidental edits - it does NOT stop you deleting a named range, so run Validate Contract after any structural edit. That is a task-pane item, not a button on any sheet, and it exists only after activation - see 'Running a simulation' below. To make deliberate changes, Review > Unprotect Sheet.
A41: Running a simulation
B42: STEP 1 - ACTIVATION, ONCE PER WORKBOOK, AND IT IS A SPECIALIST'S TASK (R-8). As it ships this workbook holds no code and no buttons: there is nothing to press and nothing is broken. A risk specialist installs the xlwings Lite add-in, adds numpy and scipy to its Environment, generates the model script by running tools/make_qra_xlwings.py in the repository, and pastes the result into the xlwings Lite editor. The Reference (xlwings) tab carries the requirements and a readable copy of the entry points. Until this is done, no simulation can run.
B43: STEP 2 - FILL THE REGISTER. Enter one risk per row on Risk Register from row 5. Blue cells are yours; the dropdowns are driven by the Lists tab. You can sort and filter the register with the sheet protected. You cannot INSERT a row: Excel inserts a whole row and the EMV columns are locked calc cells, so a 41st risk means Review > Unprotect Sheet (a specialist's step) or a register regenerated at a higher row count. Set the run controls on Settings (iterations, seed, view). If you are dollarising schedule delay, put the day rate on MC_Params - it is blank as shipped, and every schedule-dollar figure stays zero until it is filled.
B44: STEP 3 - RUN, from the xlwings Lite task pane on the right. These are task-pane items, NOT buttons on any sheet: 'Run Simulation' (the interactive count from Settings), 'Run Simulation 100k' (the deliverable count), and 'Validate Contract' (self-checks the named ranges and the version, writing PASS or FAIL). Results land on the Simulation tab, which is amber - written by the model, do not edit.
B45: WITHOUT ACTIVATION you can still do real work: fill the register and read the live expected-value totals and charts on Summary and EMV & Mode Analysis. Those are ordinary Excel formulas and need no simulation. What activation adds is the Monte-Carlo run.
B46: SPECIALIST TABS. The four Layer1_* tabs are Tier-2: they need an elicited factor model and are optional (see Layer 1 above). Simulation and Out_* are written by the model. A generalist needs none of them.
A48: Units, basis and formats - read before filling
B49: UNITS. Risk Register costs are dollars ($); time is working days. Probability and Probability (Time) are FRACTIONS between 0 and 1: 0.45 means 45%, and entering 45 makes the risk fire on every iteration, silently. Layer-1 base values and Declared_Total are $M.
B50: BASIS. Every figure is contingency at base date, before escalation. Escalation (GN4) is applied downstream to reach an outturn figure, never in this workbook.
B51: THREE-POINT INPUTS. Optimistic / Most Likely / Pessimistic are read by the Distribution column. Triangular and PERT treat Optimistic and Pessimistic as absolute bounds. Lognormal treats them as roughly P10 and P90 with a tail beyond Pessimistic, and Most Likely as the median. Binary fires the Most Likely value; Binary/PERT draws a PERT when it fires. The time three-points follow the same rule, in working days.
B52: COMPOSITION. Each iteration fires each risk with MC Include = Yes against its Probability and sums the sampled costs - MC Include is the switch, not Risk Status. A Time Impact = Yes risk shares one severity draw between its cost and its delay, so the two move together. When Layer 1 is on, each base cell is multiplied by (1 + factor) for every factor bound to it (rows via Layer1_Allocation, columns via Column_Scope) - the factor three-points are proportional deltas, 0.05 meaning +5% - and the result is added to the event total.
B53: RECORDED, NOT READ. Effectiveness_Confidence, Default_Mapping_Confidence and Assignment_Confidence are kept for a reviewer and never used by the engine: any scale, or blank.
...

Sheet Risk Register
A1: Blue cells from row 5 are yours; black cells are labels or live formulas. Hover a column header for its format. Units, basis and the three-point conventions are on TOC & Instructions.
A2: Probability is a FRACTION (0.45 = 45%). Costs are dollars, time is working days, both contingency at base date before escalation. Time Impact = Yes rows need a Mode and a Mapping row.
N3: Contingent Risk Cost | T3: Time (Working Days) | Z3: Analyst / Derived (deterministic Layer 1) | AE3: Schedule Binding (P6-ready)
A4: Risk ID | B4: Risk Status | C4: Risk Description | D4: Package | E4: RBS LVL 1 | F4: RBS LVL 2 | G4: MC Include | H4: Distribution | I4: Correlation Group | J4: Recurrence Type | K4: Causes | L4: Consequences | M4: Existing Controls | N4: Cost Impact | O4: Probability | P4: Optimistic ($) | Q4: Most Likely ($) | R4: Pessimistic ($) | S4: Basis of Estimate | T4: Time Impact | U4: Probability (Time) | V4: Optimistic (days) | W4: Most Likely (days) | X4: Pessimistic (days) | Y4: Basis of Estimate | Z4: Mode | AA4: Impact_Basis | AB4: EMV_cost ($) | AC4: EMV_sched_days | AD4: EMV_sched_dollars ($) | AE4: Schedule Activity ID (P6)
A5: RSK001 | B5: Open | O5: 0.45 | T5: Yes | U5: 0.45 | V5: 5 | W5: 12 | X5: 24 | Z5: Series | AB5: =IF(O5="","",O5*IF(OR(LOWER(H5)="pert",LOWER(H5)="binary/pert"),(P5+4*Q5+R5)/6,IF(LOWER(H5)="binary",Q5,IF(LOWER(H5)="lognormal",IF(Q5<=0,0,IF(OR(R5<=P5,R5<=0,P5<=0),ABS(Q5),Q5*EXP((MAX((LN(R5)-LN(P5))/(2*1.2816),0.01)^2)/2))),(P5+Q5+R5)/3)))) -> 0 | AC5: =IF(OR(T5<>"Yes",U5=""),0,U5*(V5+4*W5+X5)/6*IFERROR(INDEX(Methodology!$B$2:$B$20,MATCH(Z5,Methodology!$A$2:$A$20,0)),0)) -> 5.775 | AD5: =AC5*MC_day_rate -> 101062.5
A6: RSK002 | B6: Open | O6: 0.5 | T6: Yes | U6: 0.5 | V6: 3 | W6: 7 | X6: 16 | Z6: Hybrid | AB6: =IF(O6="","",O6*IF(OR(LOWER(H6)="pert",LOWER(H6)="binary/pert"),(P6+4*Q6+R6)/6,IF(LOWER(H6)="binary",Q6,IF(LOWER(H6)="lognormal",IF(Q6<=0,0,IF(OR(R6<=P6,R6<=0,P6<=0),ABS(Q6),Q6*EXP((MAX((LN(R6)-LN(P6))/(2*1.2816),0.01)^2)/2))),(P6+Q6+R6)/3)))) -> 0 | AC6: =IF(OR(T6<>"Yes",U6=""),0,U6*(V6+4*W6+X6)/6*IFERROR(INDEX(Methodology!$B$2:$B$20,MATCH(Z6,Methodology!$A$2:$A$20,0)),0)) -> 1.9583333 | AD6: =AC6*MC_day_rate -> 34270.833
A7: RSK003 | B7: Open | O7: 0.35 | T7: Yes | U7: 0.35 | V7: 1 | W7: 4 | X7: 10 | Z7: Parallel | AB7: =IF(O7="","",O7*IF(OR(LOWER(H7)="pert",LOWER(H7)="binary/pert"),(P7+4*Q7+R7)/6,IF(LOWER(H7)="binary",Q7,IF(LOWER(H7)="lognormal",IF(Q7<=0,0,IF(OR(R7<=P7,R7<=0,P7<=0),ABS(Q7),Q7*EXP((MAX((LN(R7)-LN(P7))/(2*1.2816),0.01)^2)/2))),(P7+Q7+R7)/3)))) -> 0 | AC7: =IF(OR(T7<>"Yes",U7=""),0,U7*(V7+4*W7+X7)/6*IFERROR(INDEX(Methodology!$B$2:$B$20,MATCH(Z7,Methodology!$A$2:$A$20,0)),0)) -> 0 | AD7: =AC7*MC_day_rate -> 0
A8: RSK004 | B8: Open | O8: 0.3 | T8: Yes | U8: 0.3 | V8: 6 | W8: 15 | X8: 35 | Z8: Series | AB8: =IF(O8="","",O8*IF(OR(LOWER(H8)="pert",LOWER(H8)="binary/pert"),(P8+4*Q8+R8)/6,IF(LOWER(H8)="binary",Q8,IF(LOWER(H8)="lognormal",IF(Q8<=0,0,IF(OR(R8<=P8,R8<=0,P8<=0),ABS(Q8),Q8*EXP((MAX((LN(R8)-LN(P8))/(2*1.2816),0.01)^2)/2))),(P8+Q8+R8)/3)))) -> 0 | AC8: =IF(OR(T8<>"Yes",U8=""),0,U8*(V8+4*W8+X8)/6*IFERROR(INDEX(Methodology!$B$2:$B$20,MATCH(Z8,Methodology!$A$2:$A$20,0)),0)) -> 5.05 | AD8: =AC8*MC_day_rate -> 88375
A9: RSK005 | B9: Open | O9: 0.4 | T9: Yes | U9: 0.4 | V9: 2 | W9: 6 | X9: 14 | Z9: Hybrid | AB9: =IF(O9="","",O9*IF(OR(LOWER(H9)="pert",LOWER(H9)="binary/pert"),(P9+4*Q9+R9)/6,IF(LOWER(H9)="binary",Q9,IF(LOWER(H9)="lognormal",IF(Q9<=0,0,IF(OR(R9<=P9,R9<=0,P9<=0),ABS(Q9),Q9*EXP((MAX((LN(R9)-LN(P9))/(2*1.2816),0.01)^2)/2))),(P9+Q9+R9)/3)))) -> 0 | AC9: =IF(OR(T9<>"Yes",U9=""),0,U9*(V9+4*W9+X9)/6*IFERROR(INDEX(Methodology!$B$2:$B$20,MATCH(Z9,Methodology!$A$2:$A$20,0)),0)) -> 1.3333333 | AD9: =AC9*MC_day_rate -> 23333.333
A10: RSK006 | B10: Open | O10: 0.6 | T10: No | U10: 0.6 | V10: 4 | W10: 9 | X10: 19 | Z10: Series | AB10: =IF(O10="","",O10*IF(OR(LOWER(H10)="pert",LOWER(H10)="binary/pert"),(P10+4*Q10+R10)/6,IF(LOWER(H10)="binary",Q10,IF(LOWER(H10)="lognormal",IF(Q10<=0,0,IF(OR(R10<=P10,R10<=0,P10<=0),ABS(Q10),Q10*EXP((MAX((LN(R10)-LN(P10))/(2*1.2816),0.01)^2)/2))),(P10+Q10+R10)/3)))) -> 0 | AC10: =IF(OR(T10<>"Yes",U10=""),0,U10*(V10+4*W10+X10)/6*IFERROR(INDEX(Methodology!$B$2:$B$20,MATCH(Z10,Methodology!$A$2:$A$20,0)),0)) -> 0 | AD10: =AC10*MC_day_rate -> 0
AB11: =IF(O11="","",O11*IF(OR(LOWER(H11)="pert",LOWER(H11)="binary/pert"),(P11+4*Q11+R11)/6,IF(LOWER(H11)="binary",Q11,IF(LOWER(H11)="lognormal",IF(Q11<=0,0,IF(OR(R11<=P11,R11<=0,P11<=0),ABS(Q11),Q11*EXP((MAX((LN(R11)-LN(P11))/(2*1.2816),0.01)^2)/2))),(P11+Q11+R11)/3)))) | AC11: =IF(OR(T11<>"Yes",U11=""),0,U11*(V11+4*W11+X11)/6*IFERROR(INDEX(Methodology!$B$2:$B$20,MATCH(Z11,Methodology!$A$2:$A$20,0)),0)) -> 0 | AD11: =AC11*MC_day_rate -> 0
AB12: =IF(O12="","",O12*IF(OR(LOWER(H12)="pert",LOWER(H12)="binary/pert"),(P12+4*Q12+R12)/6,IF(LOWER(H12)="binary",Q12,IF(LOWER(H12)="lognormal",IF(Q12<=0,0,IF(OR(R12<=P12,R12<=0,P12<=0),ABS(Q12),Q12*EXP((MAX((LN(R12)-LN(P12))/(2*1.2816),0.01)^2)/2))),(P12+Q12+R12)/3)))) | AC12: =IF(OR(T12<>"Yes",U12=""),0,U12*(V12+4*W12+X12)/6*IFERROR(INDEX(Methodology!$B$2:$B$20,MATCH(Z12,Methodology!$A$2:$A$20,0)),0)) -> 0 | AD12: =AC12*MC_day_rate -> 0
AB13: =IF(O13="","",O13*IF(OR(LOWER(H13)="pert",LOWER(H13)="binary/pert"),(P13+4*Q13+R13)/6,IF(LOWER(H13)="binary",Q13,IF(LOWER(H13)="lognormal",IF(Q13<=0,0,IF(OR(R13<=P13,R13<=0,P13<=0),ABS(Q13),Q13*EXP((MAX((LN(R13)-LN(P13))/(2*1.2816),0.01)^2)/2))),(P13+Q13+R13)/3)))) | AC13: =IF(OR(T13<>"Yes",U13=""),0,U13*(V13+4*W13+X13)/6*IFERROR(INDEX(Methodology!$B$2:$B$20,MATCH(Z13,Methodology!$A$2:$A$20,0)),0)) -> 0 | AD13: =AC13*MC_day_rate -> 0
AB14: =IF(O14="","",O14*IF(OR(LOWER(H14)="pert",LOWER(H14)="binary/pert"),(P14+4*Q14+R14)/6,IF(LOWER(H14)="binary",Q14,IF(LOWER(H14)="lognormal",IF(Q14<=0,0,IF(OR(R14<=P14,R14<=0,P14<=0),ABS(Q14),Q14*EXP((MAX((LN(R14)-LN(P14))/(2*1.2816),0.01)^2)/2))),(P14+Q14+R14)/3)))) | AC14: =IF(OR(T14<>"Yes",U14=""),0,U14*(V14+4*W14+X14)/6*IFERROR(INDEX(Methodology!$B$2:$B$20,MATCH(Z14,Methodology!$A$2:$A$20,0)),0)) -> 0 | AD14: =AC14*MC_day_rate -> 0
AB15: =IF(O15="","",O15*IF(OR(LOWER(H15)="pert",LOWER(H15)="binary/pert"),(P15+4*Q15+R15)/6,IF(LOWER(H15)="binary",Q15,IF(LOWER(H15)="lognormal",IF(Q15<=0,0,IF(OR(R15<=P15,R15<=0,P15<=0),ABS(Q15),Q15*EXP((MAX((LN(R15)-LN(P15))/(2*1.2816),0.01)^2)/2))),(P15+Q15+R15)/3)))) | AC15: =IF(OR(T15<>"Yes",U15=""),0,U15*(V15+4*W15+X15)/6*IFERROR(INDEX(Methodology!$B$2:$B$20,MATCH(Z15,Methodology!$A$2:$A$20,0)),0)) -> 0 | AD15: =AC15*MC_day_rate -> 0
AB16: =IF(O16="","",O16*IF(OR(LOWER(H16)="pert",LOWER(H16)="binary/pert"),(P16+4*Q16+R16)/6,IF(LOWER(H16)="binary",Q16,IF(LOWER(H16)="lognormal",IF(Q16<=0,0,IF(OR(R16<=P16,R16<=0,P16<=0),ABS(Q16),Q16*EXP((MAX((LN(R16)-LN(P16))/(2*1.2816),0.01)^2)/2))),(P16+Q16+R16)/3)))) | AC16: =IF(OR(T16<>"Yes",U16=""),0,U16*(V16+4*W16+X16)/6*IFERROR(INDEX(Methodology!$B$2:$B$20,MATCH(Z16,Methodology!$A$2:$A$20,0)),0)) -> 0 | AD16: =AC16*MC_day_rate -> 0
AB17: =IF(O17="","",O17*IF(OR(LOWER(H17)="pert",LOWER(H17)="binary/pert"),(P17+4*Q17+R17)/6,IF(LOWER(H17)="binary",Q17,IF(LOWER(H17)="lognormal",IF(Q17<=0,0,IF(OR(R17<=P17,R17<=0,P17<=0),ABS(Q17),Q17*EXP((MAX((LN(R17)-LN(P17))/(2*1.2816),0.01)^2)/2))),(P17+Q17+R17)/3)))) | AC17: =IF(OR(T17<>"Yes",U17=""),0,U17*(V17+4*W17+X17)/6*IFERROR(INDEX(Methodology!$B$2:$B$20,MATCH(Z17,Methodology!$A$2:$A$20,0)),0)) -> 0 | AD17: =AC17*MC_day_rate -> 0
AB18: =IF(O18="","",O18*IF(OR(LOWER(H18)="pert",LOWER(H18)="binary/pert"),(P18+4*Q18+R18)/6,IF(LOWER(H18)="binary",Q18,IF(LOWER(H18)="lognormal",IF(Q18<=0,0,IF(OR(R18<=P18,R18<=0,P18<=0),ABS(Q18),Q18*EXP((MAX((LN(R18)-LN(P18))/(2*1.2816),0.01)^2)/2))),(P18+Q18+R18)/3)))) | AC18: =IF(OR(T18<>"Yes",U18=""),0,U18*(V18+4*W18+X18)/6*IFERROR(INDEX(Methodology!$B$2:$B$20,MATCH(Z18,Methodology!$A$2:$A$20,0)),0)) -> 0 | AD18: =AC18*MC_day_rate -> 0
AB19: =IF(O19="","",O19*IF(OR(LOWER(H19)="pert",LOWER(H19)="binary/pert"),(P19+4*Q19+R19)/6,IF(LOWER(H19)="binary",Q19,IF(LOWER(H19)="lognormal",IF(Q19<=0,0,IF(OR(R19<=P19,R19<=0,P19<=0),ABS(Q19),Q19*EXP((MAX((LN(R19)-LN(P19))/(2*1.2816),0.01)^2)/2))),(P19+Q19+R19)/3)))) | AC19: =IF(OR(T19<>"Yes",U19=""),0,U19*(V19+4*W19+X19)/6*IFERROR(INDEX(Methodology!$B$2:$B$20,MATCH(Z19,Methodology!$A$2:$A$20,0)),0)) -> 0 | AD19: =AC19*MC_day_rate -> 0
AB20: =IF(O20="","",O20*IF(OR(LOWER(H20)="pert",LOWER(H20)="binary/pert"),(P20+4*Q20+R20)/6,IF(LOWER(H20)="binary",Q20,IF(LOWER(H20)="lognormal",IF(Q20<=0,0,IF(OR(R20<=P20,R20<=0,P20<=0),ABS(Q20),Q20*EXP((MAX((LN(R20)-LN(P20))/(2*1.2816),0.01)^2)/2))),(P20+Q20+R20)/3)))) | AC20: =IF(OR(T20<>"Yes",U20=""),0,U20*(V20+4*W20+X20)/6*IFERROR(INDEX(Methodology!$B$2:$B$20,MATCH(Z20,Methodology!$A$2:$A$20,0)),0)) -> 0 | AD20: =AC20*MC_day_rate -> 0
AB21: =IF(O21="","",O21*IF(OR(LOWER(H21)="pert",LOWER(H21)="binary/pert"),(P21+4*Q21+R21)/6,IF(LOWER(H21)="binary",Q21,IF(LOWER(H21)="lognormal",IF(Q21<=0,0,IF(OR(R21<=P21,R21<=0,P21<=0),ABS(Q21),Q21*EXP((MAX((LN(R21)-LN(P21))/(2*1.2816),0.01)^2)/2))),(P21+Q21+R21)/3)))) | AC21: =IF(OR(T21<>"Yes",U21=""),0,U21*(V21+4*W21+X21)/6*IFERROR(INDEX(Methodology!$B$2:$B$20,MATCH(Z21,Methodology!$A$2:$A$20,0)),0)) -> 0 | AD21: =AC21*MC_day_rate -> 0
AB22: =IF(O22="","",O22*IF(OR(LOWER(H22)="pert",LOWER(H22)="binary/pert"),(P22+4*Q22+R22)/6,IF(LOWER(H22)="binary",Q22,IF(LOWER(H22)="lognormal",IF(Q22<=0,0,IF(OR(R22<=P22,R22<=0,P22<=0),ABS(Q22),Q22*EXP((MAX((LN(R22)-LN(P22))/(2*1.2816),0.01)^2)/2))),(P22+Q22+R22)/3)))) | AC22: =IF(OR(T22<>"Yes",U22=""),0,U22*(V22+4*W22+X22)/6*IFERROR(INDEX(Methodology!$B$2:$B$20,MATCH(Z22,Methodology!$A$2:$A$20,0)),0)) -> 0 | AD22: =AC22*MC_day_rate -> 0
... AB44: =IF(O44="","",O44*IF(OR(LOWER(H44)="pert",LOWER(H44)="binary/pert"),(P44+4*Q44+R44)/6,IF(LOWER(H44)="binary",Q44,IF(LOWER(H44)="lognormal",IF(Q44<=0,0,IF(OR(R44<=P44,R44<=0,P44<=0),ABS(Q44),Q44*EXP((MAX((LN(R44)-LN(P44))/(2*1.2816),0.01)^2)/2))),(P44+Q44+R44)/3)))) | AC44: =IF(OR(T44<>"Yes",U44=""),0,U44*(V44+4*W44+X44)/6*IFERROR(INDEX(Methodology!$B$2:$B$20,MATCH(Z44,Methodology!$A$2:$A$20,0)),0)) -> 0 | AD44: =AC44*MC_day_rate -> 0

Sheet Lists
A1: Cascade lists - edit here; the Risk Register dropdowns follow.
A2: Distribution | B2: MCInclude | C2: TimeImpact | D2: Recurrence | E2: Mode | F2: CGCode | G2: RBS_L1 | H2: RBS_L2 | I2: Package | J2: Factor
A3: PERT | B3: Yes | C3: Yes | D3: Single | E3: Series | F3: CG01 | G3: Technical | H3: Design | I3: Civil | J3: Labour rate
A4: Triangular | B4: No | C4: No | D4: Recurring | E4: Hybrid | F4: CG02 | G4: Commercial | H4: Construction | I4: Structural | J4: Material rate
A5: Lognormal | D5: None | E5: Parallel | F5: CG03 | G5: Management | H5: Procurement | I5: Mechanical | J5: Plant rate
A6: Binary | F6: CG04 | G6: External | H6: Interface | I6: Electrical | J6: Productivity
A7: Binary/PERT | F7: CG05 | G7: Environmental | H7: Approvals | I7: Piping | J7: Quantity growth
F8: CG06 | G8: Delivery | H8: Weather | I8: Instrumentation | J8: FX
F9: CG07 | H9: Ground Conditions | I9: Commissioning | J9: Escalation
F10: CG08 | H10: Commissioning | I10: Management
F11: CG09
F12: CG10
F13: CG11
F14: CG12
F15: CG13

Sheet Mapping
A1: P6/CPM binding for schedule (Time=Yes) risks. Blue cells are yours. The header row is the contract and is locked; hover a header for its format. Units and basis: TOC & Instructions.
A2: Prefix_List: ONE activity-code prefix, despite the column name — e.g. `20.` to bind every activity whose code starts with 20, or a full code to bind exactly one. A trailing dot is stripped. Blank = the risk binds nothing and contributes no delay.
A3: Injection_Method: How the sampled delay is applied to the bound activities. One of: additive_pert_days, discrete_event_additive_days, productivity_multiplicative_factor. Blank = use the register default, Methodology!Default_Injection_Method.
A4: Gating_Activity_ID: The single activity this risk gates, as it appears in the schedule. An ID that names no activity is SKIPPED, not guessed — the risk then falls back to the programme profile with nothing on screen saying so.
A6: Risk ID | B6: Pattern_ID | C6: Prefix_List | D6: Activity_Count | E6: Gating_Activity_ID | F6: Injection_Method

Sheet Risk_Activity_Patterns
A1: Schedule risk-to-activity patterns - workshop input, you fill this. Blue cells are yours. The header row is the contract and is locked; hover a header for its format. Units and basis: TOC & Instructions.
A2: Default_Mapping_Confidence: Free text — any scale you like, or leave it blank. Nothing in the engine reads it; it is provenance for whoever reviews the mapping. Blank = nothing; the engine does not read this column.
A4: Pattern_ID | B4: Description | C4: Prefix_List | D4: Is_Cost_Only | E4: Default_Mapping_Confidence | F4: Reconciliation_Treatment | G4: Example_Risk_IDs | H4: Notes

Sheet Risk_Pattern_Assignments
A1: Per-risk pattern assignment - workshop input, you fill this. Blue cells are yours. The header row is the contract and is locked; hover a header for its format. Units and basis: TOC & Instructions.
A2: Assignment_Confidence: Free text, as for Default_Mapping_Confidence. Read into the frame and never used in a calculation. Blank = nothing; the engine does not read this column.
A4: Risk_ID | B4: Pattern_ID | C4: Assignment_Confidence | D4: Notes

Sheet Treatments
A1: Per-risk treatments + effectiveness - workshop input, you fill this. Blue cells are yours. The header row is the contract and is locked; hover a header for its format. Units and basis: TOC & Instructions.
A2: Effectiveness_Pct: A PERCENTAGE: enter 30 for 30%. The engine also accepts a 0-1 fraction and splits the two at 1.0 — so 1.0 is read as 1%, NOT as fully effective. Enter 100 for a fully effective treatment.
A3: Effectiveness_Confidence: Free text. Record how firm the effectiveness estimate is, in your own words.
A5: Risk_ID | B5: Treatment_Description | C5: Effectiveness_Pct | D5: Effectiveness_Confidence

Sheet Summary
A1: Total EMV days (PERT) | B1: =SUMPRODUCT(('Risk Register'!T5:T44="Yes")*'Risk Register'!U5:U44*('Risk Register'!V5:V44+4*'Risk Register'!W5:W44+'Risk Register'!X5:X44)/6) -> 18.983333 | D1: CALCULATED - live formulas over the Risk Register (the SRA calibration comparators). Do not type; edit the register.
A2: Total EMV $ cost-of-delay (PERT) | B2: =B1*MC_day_rate -> 332208.33
A3: Aggregate finish-date slippage days (PERT) | B3: =SUM('Risk Register'!AC5:AC44) -> 14.116667
A4: Aggregate finish-date slippage $ (PERT) | B4: =B3*MC_day_rate -> 247041.67

Sheet MC_Params
B2: Iterations (n)
B3: Random seed (0=random)
B4: Stakeholder view
B5: Reporting P-Level (pct)
B6: TIC - Total Installed Cost ($)
B7: Cascade enabled
B8: Cascade slip rate
B9: Cascade slip cap
B10: Cascade cost scale
B11: day_rate ($/wd) | C11: 17500
B12: programme_seasons
B13: cp_hybrid_float_threshold_days
B14: schedule duration (weeks)
B15: expected_time_yes_count

Sheet EMV & Mode Analysis
A1: EMV & Mode Analysis - this project
A2: Deterministic Layer-1 expected values (means) from the register EMV columns, NOT Monte-Carlo P-levels. Live formulas; refresh on open.
A3: DERIVED - populated from the register's EMV columns whenever it is filled or a run happens. Do not type.
A4: Layer-1 totals
A5: Total cost EMV ($) | B5: =SUM('Risk Register'!AB5:AB44) -> 0
A6: Total schedule EMV ($) | B6: =SUM('Risk Register'!AD5:AD44) -> 247041.67
A7: Total Layer-1 EMV ($) | B7: =B5+B6 -> 247041.67
A8: Risks: Series / Hybrid / Parallel | B8: =COUNTIF('Risk Register'!Z5:Z44,"Series")&" / "&COUNTIF('Risk Register'!Z5:Z44,"Hybrid")&" / "&COUNTIF('Risk Register'!Z5:Z44,"Parallel") -> 3 / 2 / 1
A11: Risk | B11: Cost EMV ($)
A12: ='Risk Register'!A5 -> RSK001 | B12: ='Risk Register'!AB5 -> 0
A13: ='Risk Register'!A6 -> RSK002 | B13: ='Risk Register'!AB6 -> 0
A14: ='Risk Register'!A7 -> RSK003 | B14: ='Risk Register'!AB7 -> 0
A15: ='Risk Register'!A8 -> RSK004 | B15: ='Risk Register'!AB8 -> 0
A16: ='Risk Register'!A9 -> RSK005 | B16: ='Risk Register'!AB9 -> 0
A17: ='Risk Register'!A10 -> RSK006 | B17: ='Risk Register'!AB10 -> 0
A18: ='Risk Register'!A11 -> 0 | B18: ='Risk Register'!AB11
A19: ='Risk Register'!A12 -> 0 | B19: ='Risk Register'!AB12
A20: ='Risk Register'!A13 -> 0 | B20: ='Risk Register'!AB13
A21: ='Risk Register'!A14 -> 0 | B21: ='Risk Register'!AB14
A22: ='Risk Register'!A15 -> 0 | B22: ='Risk Register'!AB15
A23: ='Risk Register'!A16 -> 0 | B23: ='Risk Register'!AB16
... A51: ='Risk Register'!A44 -> 0 | B51: ='Risk Register'!AB44
A54: Risk | B54: Schedule EMV ($)
A55: ='Risk Register'!A5 -> RSK001 | B55: ='Risk Register'!AD5 -> 101062.5
A56: ='Risk Register'!A6 -> RSK002 | B56: ='Risk Register'!AD6 -> 34270.833
A57: ='Risk Register'!A7 -> RSK003 | B57: ='Risk Register'!AD7 -> 0
A58: ='Risk Register'!A8 -> RSK004 | B58: ='Risk Register'!AD8 -> 88375
A59: ='Risk Register'!A9 -> RSK005 | B59: ='Risk Register'!AD9 -> 23333.333
A60: ='Risk Register'!A10 -> RSK006 | B60: ='Risk Register'!AD10 -> 0
A61: ='Risk Register'!A11 -> 0 | B61: ='Risk Register'!AD11 -> 0
A62: ='Risk Register'!A12 -> 0 | B62: ='Risk Register'!AD12 -> 0
A63: ='Risk Register'!A13 -> 0 | B63: ='Risk Register'!AD13 -> 0
A64: ='Risk Register'!A14 -> 0 | B64: ='Risk Register'!AD14 -> 0
A65: ='Risk Register'!A15 -> 0 | B65: ='Risk Register'!AD15 -> 0
A66: ='Risk Register'!A16 -> 0 | B66: ='Risk Register'!AD16 -> 0
... A94: ='Risk Register'!A44 -> 0 | B94: ='Risk Register'!AD44 -> 0
A97: Layer | B97: EMV ($)
A98: Cost | B98: =B5 -> 0
A99: Schedule | B99: =B6 -> 247041.67

Sheet Layer1_Base
A1: WBS Row | B1: Staff | C1: Labour | D1: Plant | E1: Concrete | F1: Steel | G1: General | H1: Subcontract | I1: Provisional
A2: WBS-01
A3: WBS-02
A4: WBS-03
A5: WBS-04
A6: WBS-05
A7: WBS-06
A8: WBS-07
A9: WBS-08
A10: WBS-09
A11: WBS-10
A12: WBS-11
A13: WBS-12
A15: Declared_Total ($M)
A16: Units | B16: $M (read x 1,000,000 -> dollars)

Sheet Layer1_Factors
A1: Factor | B1: Driver | C1: Opt_P10 | D1: ML_mode | E1: P90 | F1: Column_Scope

Sheet Layer1_Allocation
A1: Factor | B1: WBS-01 | C1: WBS-02 | D1: WBS-03 | E1: WBS-04 | F1: WBS-05 | G1: WBS-06 | H1: WBS-07 | I1: WBS-08 | J1: WBS-09 | K1: WBS-10 | L1: WBS-11 | M1: WBS-12

Sheet Layer1_Correlation
A1: Corr_Mode | B1: elicited | C1: (zero | elicited | one)
A2: PSD_Status | B2: valid | C2: (reader recomputes via Corr_flag)
A4: Factor

Sheet Methodology
A1: CG code / Mode | B1: Coefficient / Multiplier | C1: Description
A2: CG01 | B2: 0.5
A3: CG02 | B3: 0.5
A4: CG03 | B4: 0.5
A5: CG04 | B5: 0.5
A6: CG05 | B6: 0.5
A7: CG06 | B7: 0.5
A8: CG07 | B8: 0.5
A9: CG08 | B9: 0.5
A10: CG09 | B10: 0.5
A11: CG10 | B11: 0.5
A12: CG11 | B12: 0.5
A13: CG12 | B13: 0.5
... A17: Parallel | B17: 0
A18: Cost_Calibration_Tolerance_Dollars | B18: 50000 | C18: Cost cross-check: absolute tolerance ($)
A19: Cost_Calibration_Tolerance_Pct | B19: 0.001 | C19: Cost cross-check: relative tolerance (fraction)
A20: Schedule_Calibration_Tolerance_Days | B20: 1 | C20: Schedule cross-check: absolute tolerance (days)
A21: Schedule_Calibration_Tolerance_Pct | B21: 0.05 | C21: Schedule cross-check: relative tolerance (fraction)
A22: Schedule_Top3_Tie_Tolerance_Pct | B22: 0.02 | C22: Schedule top-3 cross-check: two contributors the arms rank apart are one tie when within this fraction of each other in BOTH arms
A23: Default_Injection_Method | B23: discrete_event_additive_days | C23: Dual-coded risks with no Injection_Method on the Mapping sheet take this

Sheet Settings
A1: Iterations (interactive default) | B1: 25000
A2: Random seed | B2: 42
A3: View (owner | shared-pool) | B3: owner
A4: Risk-ID prefix | B4: RSK
A5: Iterations (100k on-demand button) | B5: 100000
A6: Contract version | B6: 1.4
A7: Pyodide runtime pin | B7: 314.0.1
A8: Layer 1 enabled (TRUE/FALSE) | B8: FALSE

Sheet Simulation
A1: P-level | B1: Cost ($) | D1: Cum. prob | E1: Cost ($) | G1: Corr_flag | I1: P-level | J1: rho=0 | K1: elicited | L1: rho=1 | N1: Contract validation
G3: P80 CI half-width (25k)
G4: P80 CI half-width (%)
G6: Amber cells are written by the model (xlwings) - do not edit.
A22: MODEL-WRITTEN - do not type on this sheet. Every cell here is overwritten on each run.

Sheet Reference (xlwings)
A1: xlwings Lite - requirements & code (paste-once)
A2: REFERENCE - the paste-once script and its requirements. Nothing to fill.
A3: Requirements (xlwings Lite -> Environment)
A4: numpy
A5: scipy
A6: Pyodide runtime: 314.0.1 (ratified Q4; do not float)
A8: How to load the model code
A9: Generate the pasteable script with python tools/make_qra_xlwings.py -> dist/qra_xlwings_combined.py, then paste it into the xlwings Lite editor. That generated file is the source of truth (byte-parity gated to the repo engine); do not hand-edit. The text below is a human-readable convenience copy of the @script entry points only.
A11: Buttons (xlwings Lite task pane - one per @script)
A12: Run Simulation | B12: cost-QRA at the interactive count (Settings B1 / Set_iterations, default 25,000).
A13: Run Simulation 100k | B13: cost-QRA at the on-demand 100,000 count (Settings B5 / Set_iterations_max) - the deliverable run.
A14: Validate Contract | B14: self-check the named-range contract + version + methodology; writes PASS/FAIL to Out_validation.
A16: src/tier1_xlwings_shell.py (@script source - convenience copy)
A17: """QRAXL-01 Tier-1 xlwings Lite shell (front-end I/O layer).
A19: The @script entry point the xlwings Lite runtime calls with the open workbook.
A20: It reads the contract-v2 register via xlwings ranges, feeds the cell GRIDS to the
A21: SHARED parser (``qra_register_parse`` - the same one Tier 2 uses, so Tier-1 ==
A22: Tier-2 on the read side by construction), then runs ``qra_core`` and writes the
A23: P-curve back.
A25: The @script is a THIN I/O wrapper over the headless-testable
A26: ``tier1_headless.run_headless`` (read ranges -> call the headless run -> write
A27: ranges), mirroring RF-01 (rf_headless.py is the runner, shell_xlwings.py the
A28: I/O). CI covers the compute + formatting; only the literal xlwings range read/
A29: write is Excel-only. ``qra_core``, the parser and the resolver stay Pyodide-
... A266: ["PASS" if ok else "FAIL"], [message]]
